<mujocoinclude>
    <body name="taitan" pos="0 0 -0.09" quat="1 0 0 0">
        <joint name="float_base" type="free"/>
        <inertial pos="0.005 0 0.054" quat="1 0 0 0" mass="3.4" diaginertia="0.036 0.035 0.011"/>  
        <geom type="mesh" contype="0" conaffinity="0" group="1" rgba="1 1 1 1" mesh="base_link" />
        <!-- <geom type="mesh" rgba="1 1 1 1" mesh="base_link" /> -->
        <site name='imu' size='0.01' pos='0.0 0 0.0'/>
        <body name="L0_Link" pos="0 0.0444706 -0.0372">
            <inertial pos="-0.00294137 -2.54825e-05 -0.041079" mass="0.389944" diaginertia="0.0003 0.0002 0.0002" />
            <joint name="J_L0" pos="0 0 0" axis="0 0 1" limited="true" range="-0.6 0.6" />
            <geom type="mesh" contype="0" conaffinity="0" group="1" rgba="0.898039 0.917647 0.929412 1" mesh="L0_Link" />
            <geom type="mesh" rgba="0.898039 0.917647 0.929412 1" mesh="L0_Link" />
            <body name="L1_Link" pos="0.0104583 0 -0.0438695">
                <inertial pos="-0.000428254 0.0256328 -0.00860134" quat="0.707107 0.707107 0 0" mass="0.0748964" diaginertia="4.31603e-05 3.47985e-05 2.12457e-05" />
                <joint name="J_L1" pos="0 0 0" axis="-1 0 0" limited="true" range="-0.37 0.49" />
                <geom type="mesh" contype="0" conaffinity="0" group="1" rgba="0.898039 0.917647 0.929412 1" mesh="L1_Link" />
                <!-- <geom type="mesh" rgba="0.898039 0.917647 0.929412 1" mesh="L1_Link" /> -->
                <body name="L2_Link" pos="-0.0119583 0.0498124 -0.0144835">
                    <inertial pos="0.000814289 0.0183404 -0.0736652" quat="0.707107 0 0 0.707107" mass="1.35024" diaginertia="0.0082 0.0075 0.0009" />
                    <joint name="J_L2" pos="0 0 0" axis="0 1 0" limited="true" range="-1.57 1.57" />
                    <geom type="mesh" contype="0" conaffinity="0" group="1" rgba="0.792157 0.819608 0.933333 1" mesh="L2_Link" />
                    <geom type="mesh" rgba="0.792157 0.819608 0.933333 1" mesh="L2_Link" />
                    <body name="L3_Link" pos="0 0.0025 -0.147378">
                        <inertial pos="-2.5603e-05 0.00525835 -0.11753" quat="0.706246 0.0348808 -0.0348808 0.706246" mass="0.511661" diaginertia="0.0012099 0.0011 0.000190098" />
                        <joint name="J_L3" pos="0 0 0" axis="0 1 0" limited="true" range="0 2.35" />
                        <geom type="mesh" contype="0" conaffinity="0" group="1" rgba="1 1 1 1" mesh="L3_Link" />
                        <geom type="mesh" rgba="1 1 1 1" mesh="L3_Link" />
                        <body name="L4_Link_ankel" pos="0 0.023 -0.140491">
                            <inertial pos="0.011854 -0.00567826 -0.0279832" quat="0.5 0.5 0.5 0.5" mass="0.153123" diaginertia="0.0003 0.0003 0.0001" />
                            <joint name="J_L4_ankel" pos="0 0 0" axis="0 -1 0" limited="true" range="-0.95 0.95" />
                            <geom type="mesh" contype="0" conaffinity="0" group="1" rgba="1 1 1 1" mesh="L4_Link" />
                            <geom type="mesh" rgba="1 1 1 1" mesh="L4_Link" />
                        </body>
                    </body>
                </body>
            </body>
        </body>
        <body name="R0_Link" pos="0 -0.0444706 -0.0377">
            <inertial pos="-0.00294137 -2.55329e-05 -0.040579" mass="0.389944" diaginertia="0.0003 0.0002 0.0002" />
            <joint name="J_R0" pos="0 0 0" axis="0 0 1" limited="true" range="-0.6 0.6" />
            <geom type="mesh" contype="0" conaffinity="0" group="1" rgba="0.898039 0.917647 0.929412 1" mesh="R0_Link" />
            <geom type="mesh" rgba="0.898039 0.917647 0.929412 1" mesh="R0_Link" />
            <body name="R1_Link" pos="0.0104583 0 -0.0433695">
                <inertial pos="-0.000417158 -0.025598 -0.00859271" quat="0.707107 0.707107 0 0" mass="0.0747885" diaginertia="4.30775e-05 3.47137e-05 2.12071e-05" />
                <joint name="J_R1" pos="0 0 0" axis="-1 0 0" limited="true" range="-0.49 0.37" />
                <geom type="mesh" contype="0" conaffinity="0" group="1" rgba="0.898039 0.917647 0.929412 1" mesh="R1_Link" />
                <!-- <geom type="mesh" rgba="0.898039 0.917647 0.929412 1" mesh="R1_Link" /> -->
                <body name="R2_Link" pos="-0.0119583 -0.0522803 -0.0144835">
                    <inertial pos="0.000815124 -0.0158195 -0.0738433" quat="0.707107 0 0 0.707107" mass="1.34863" diaginertia="0.0082 0.0075 0.0009" />
                    <joint name="J_R2" pos="0 0 0" axis="0 -1 0" limited="true" range="-1.57 1.57" />
                    <geom type="mesh" contype="0" conaffinity="0" group="1" rgba="0.792157 0.819608 0.933333 1" mesh="R2_Link" />
                    <geom type="mesh" rgba="0.792157 0.819608 0.933333 1" mesh="R2_Link" />
                    <body name="R3_Link" pos="0 0 -0.147378">
                        <inertial pos="2.2154e-05 -0.00575835 -0.117628" quat="0.706246 -0.0348808 0.0348808 0.706246" mass="0.511661" diaginertia="0.0012099 0.0011 0.000190098" />
                        <joint name="J_R3" pos="0 0 0" axis="0 -1 0" limited="true" range="-2.35 0" />
                        <geom type="mesh" contype="0" conaffinity="0" group="1" rgba="1 1 1 1" mesh="R3_Link" />
                        <geom type="mesh" rgba="1 1 1 1" mesh="R3_Link" />
                        <body name="R4_Link_ankel" pos="0 -0.0235 -0.140629">
                            <inertial pos="0.0140716 0.00554706 -0.0279863" quat="0.5 0.5 0.5 0.5" mass="0.147848" diaginertia="0.0003 0.0003 0.0001" />
                            <joint name="J_R4_ankel" pos="0 0 0" axis="0 -1 0" limited="true" range="-0.95 0.95" />
                            <geom type="mesh" contype="0" conaffinity="0" group="1" rgba="1 1 1 1" mesh="R4_Link" />
                            <geom type="mesh" rgba="1 1 1 1" mesh="R4_Link" />
                        </body>
                    </body>
                </body>
            </body>
        </body>
    </body>
</mujocoinclude>

