<?xml version="1.0" encoding="utf-8"?>
<!-- This URDF was automatically created by SolidWorks to URDF Exporter! Originally created by Stephen Brawner (brawner@gmail.com) 
     Commit Version: 1.6.0-4-g7f85cfe  Build Version: 1.6.7995.38578
     For more information, please see http://wiki.ros.org/sw_urdf_exporter -->
<robot
  name="tinker_urdf">
  <mujoco>
    <compiler
    	meshdir="../meshes/"
    	balanceinertia="true"
    	discardvisual="false" />
  </mujoco>
  <link
    name="base_link">
    <inertial>
      <origin
        xyz="-0.030553 0.00030132 0.020883"
        rpy="0 0 0" />
      <mass
        value="2.77927858" />
      <inertia
        ixx="0.01186984"
        ixy="4.282E-05"
        ixz="-0.0005233"
        iyy="0.01506257"
        iyz="2.5E-06"
        izz="0.01339558" />
    </inertial>
    <visual>
      <origin
        xyz="0 0 0"
        rpy="0 0 0" />
      <geometry>
        <mesh
          filename="../meshes/base_link.STL" />
      </geometry>
      <material
        name="">
        <color
          rgba="1 1 1 1" />
      </material>
    </visual>
    <collision>
      <origin
        xyz="0 0 0"
        rpy="0 0 0" />
      <geometry>
        <mesh
          filename="../meshes/base_link.STL" />
      </geometry>
    </collision>
  </link>
  <link
    name="link_l_yaw">
    <inertial>
      <origin
        xyz="0.0031721 3.773E-05 -0.050777"
        rpy="0 0 0" />
      <mass
        value="0.625" />
      <inertia
        ixx="0.00055903"
        ixy="-2E-07"
        ixz="-9.8E-06"
        iyy="0.00033872"
        iyz="-2.5E-07"
        izz="0.00030229" />
    </inertial>
    <visual>
      <origin
        xyz="0 0 0"
        rpy="0 0 0" />
      <geometry>
        <mesh
          filename="../meshes/link_l_yaw.STL" />
      </geometry>
      <material
        name="">
        <color
          rgba="0.89804 0.91765 0.92941 1" />
      </material>
    </visual>
    <!--collision>
      <origin
        xyz="0 0 0"
        rpy="0 0 0" />
      <geometry>
        <mesh
          filename="../meshes/link_l_yaw.STL" />
      </geometry>
    </collision-->
  </link>
  <joint
    name="joint_l_yaw"
    type="revolute">
    <origin
      xyz="0.0025357 0.053301 0.056145"
      rpy="0 0 0" />
    <parent
      link="base_link" />
    <child
      link="link_l_yaw" />
    <axis
      xyz="0 0 1" />
    <limit
      lower="-0.66"
      upper="0.66"
      effort="6"
      velocity="14" />
  </joint>
  <link
    name="link_l_roll">
    <inertial>
      <origin
        xyz="0.0090994 0.06545 -0.013394"
        rpy="0 0 0" />
      <mass
        value="0.647801" />
      <inertia
        ixx="0.00044577"
        ixy="-4.2E-05"
        ixz="6.58E-06"
        iyy="0.000499"
        iyz="2.618E-05"
        izz="0.0004444" />
    </inertial>
    <visual>
      <origin
        xyz="0 0 0"
        rpy="0 0 0" />
      <geometry>
        <mesh
          filename="../meshes/link_l_roll.STL" />
      </geometry>
      <material
        name="">
        <color
          rgba="0.89804 0.91765 0.92941 1" />
      </material>
    </visual>
    <!--collision>
      <origin
        xyz="0 0 0"
        rpy="0 0 0" />
      <geometry>
        <mesh
          filename="../meshes/link_l_roll.STL" />
      </geometry>
    </collision-->
  </link>
  <joint
    name="joint_l_roll"
    type="revolute">
    <origin
      xyz="-0.010958 0 -0.054965"
      rpy="0 0 0" />
    <parent
      link="link_l_yaw" />
    <child
      link="link_l_roll" />
    <axis
      xyz="1 0 0" />
    <limit
      lower="-0.57"
      upper="0.57"
      effort="12"
      velocity="14" />
  </joint>
  <link
    name="link_l_pitch">
    <inertial>
      <origin
        xyz="-0.0013138 0.0056716 -0.12051"
        rpy="0 0 0" />
      <mass
        value="0.7406" />
      <inertia
        ixx="0.0014693"
        ixy="5.66E-06"
        ixz="2.87E-05"
        iyy="0.0017566"
        iyz="-0.00011948"
        izz="0.00041153" />
    </inertial>
    <visual>
      <origin
        xyz="0 0 0"
        rpy="0 0 0" />
      <geometry>
        <mesh
          filename="../meshes/link_l_pitch.STL" />
      </geometry>
      <material
        name="">
        <color
          rgba="1 1 1 1" />
      </material>
    </visual>
    <!-- <collision>
      <origin
        xyz="0 0 0"
        rpy="0 0 0" />
      <geometry>
        <mesh
          filename="../meshes/link_l_pitch.STL" />
      </geometry>
    </collision> -->
  </link>
  <joint
    name="joint_l_pitch"
    type="revolute">
    <origin
      xyz="0.010958 0.071699 -0.014313"
      rpy="0 0 0" />
    <parent
      link="link_l_roll" />
    <child
      link="link_l_pitch" />
    <axis
      xyz="0 1 0" />
    <limit
      lower="-0.57"
      upper="1.57"
      effort="12"
      velocity="14" />
  </joint>
  <link
    name="link_l_knee">
    <inertial>
      <origin
        xyz="-2.3595E-06 -0.0058981 -0.11387"
        rpy="0 0 0" />
      <mass
        value="0.4956" />
      <inertia
        ixx="0.00095008"
        ixy="-2E-08"
        ixz="8E-08"
        iyy="0.0010388"
        iyz="9.52E-05"
        izz="0.00017304" />
    </inertial>
    <visual>
      <origin
        xyz="0 0 0"
        rpy="0 0 0" />
      <geometry>
        <mesh
          filename="../meshes/link_l_knee.STL" />
      </geometry>
      <material
        name="">
        <color
          rgba="1 1 1 1" />
      </material>
    </visual>
    <collision>
      <origin
        xyz="0 0 0"
        rpy="0 0 0" />
      <geometry>
        <mesh
          filename="../meshes/link_l_knee.STL" />
      </geometry>
    </collision>
  </link>
  <joint
    name="joint_l_knee"
    type="revolute">
    <origin
      xyz="0 0 -0.14738"
      rpy="0 0 0" />
    <parent
      link="link_l_pitch" />
    <child
      link="link_l_knee" />
    <axis
      xyz="0 1 0" />
    <limit
      lower="-2.57"
      upper="0.05"
      effort="12"
      velocity="14" />
  </joint>
  <link
    name="link_l_ankle">
    <inertial>
      <origin
        xyz="0.014325 0.0093511 -0.027539"
        rpy="0 0 0" />
      <mass
        value="0.1122" />
      <inertia
        ixx="4.419E-05"
        ixy="3.36E-06"
        ixz="5.65E-06"
        iyy="0.00021868"
        iyz="-7.06E-06"
        izz="0.00020728" />
    </inertial>
    <visual>
      <origin
        xyz="0 0 0"
        rpy="0 0 0" />
      <geometry>
        <mesh
          filename="../meshes/link_l_ankle.STL" />
      </geometry>
      <material
        name="">
        <color
          rgba="1 0.90588 0.91765 1" />
      </material>
    </visual>
    <!-- <collision>
      <origin
        xyz="0 0 0"
        rpy="0 0 0" />
      <geometry>
        <mesh
          filename="../meshes/link_l_ankle.STL" />
      </geometry>
    </collision> -->
    <collision>
      <origin
        xyz="0.013 0.005 -0.049"
        rpy="0 0 0" />
      <geometry>
        <box size="0.13 0.04 0.005"/>
      </geometry>
    </collision>
  </link>
  <joint
    name="joint_l_ankle"
    type="revolute">
    <origin
      xyz="0 0 -0.14049"
      rpy="0 0 0" />
    <parent
      link="link_l_knee" />
    <child
      link="link_l_ankle" />
    <axis
      xyz="0 1 0" />
    <limit
      lower="-0.57"
      upper="1.57"
      effort="6"
      velocity="14" />
  </joint>
  <!--link
    name="link_l_foot">
     <inertial>
      <origin
        xyz="0.020853 0.0048146 -0.030186"
        rpy="0 0 0" />
      <mass
        value="0.01" />
      <inertia
        ixx="0.00001"
        ixy="0.0"
        ixz="0.0"
        iyy="0.00001"
        iyz="-0.0"
        izz="0.00001" />
    </inertial>
    <collision>
      <origin
        xyz="0.015 0 0"
        rpy="0 1.54 0" />
      <geometry>
        <cylinder length="0.15" radius="0.01"/>
      </geometry>
    </collision>
  </link>
  <joint
    name="l_foot_joint"
    type="fixed" dont_collapse="true">
    <origin
      xyz="0 0 -0.05"
      rpy="0 0 0" />
    <parent
      link="link_l_ankle" />
    <child
      link="link_l_foot" />
    <axis
      xyz="0 0 0" />
  </joint-->


  <link
    name="link_r_yaw">
    <inertial>
      <origin
        xyz="0.0031721 3.773E-05 -0.050777"
        rpy="0 0 0" />
      <mass
        value="0.625" />
      <inertia
        ixx="0.00055903"
        ixy="-2E-07"
        ixz="-9.8E-06"
        iyy="0.00033872"
        iyz="-2.5E-07"
        izz="0.00030229" />
    </inertial>
    <visual>
      <origin
        xyz="0 0 0"
        rpy="0 0 0" />
      <geometry>
        <mesh
          filename="../meshes/link_r_yaw.STL" />
      </geometry>
      <material
        name="">
        <color
          rgba="0.89804 0.91765 0.92941 1" />
      </material>
    </visual>
    <!--collision>
      <origin
        xyz="0 0 0"
        rpy="0 0 0" />
      <geometry>
        <mesh
          filename="../meshes/link_r_yaw.STL" />
      </geometry>
    </collision-->
  </link>
  <joint
    name="joint_r_yaw"
    type="revolute">
    <origin
      xyz="0.0025357 -0.053425 0.056145"
      rpy="0 0 0" />
    <parent
      link="base_link" />
    <child
      link="link_r_yaw" />
    <axis
      xyz="0 0 1" />
    <limit
      lower="-0.66"
      upper="0.66"
      effort="6"
      velocity="14" />
  </joint>
  <link
    name="link_r_roll">
    <inertial>
      <origin
        xyz="0.0090994 -0.06469 -0.013394"
        rpy="0 0 0" />
      <mass
        value="0.647601" />
      <inertia
        ixx="0.00043985"
        ixy="4.113E-05"
        ixz="6.56E-06"
        iyy="0.00049891"
        iyz="-2.574E-05"
        izz="0.00043848" />
    </inertial>
    
    <visual>
      <origin
        xyz="0 0 0"
        rpy="0 0 0" />
      <geometry>
        <mesh
          filename="../meshes/link_r_roll.STL" />
      </geometry>
      <material
        name="">
        <color
          rgba="0.89804 0.91765 0.92941 1" />
      </material>
    </visual>
    <!--collision>
      <origin
        xyz="0 0 0"
        rpy="0 0 0" />
      <geometry>
        <mesh
          filename="../meshes/link_r_roll.STL" />
      </geometry>
    </collision-->
  </link>
  <joint
    name="joint_r_roll"
    type="revolute">
    <origin
      xyz="-0.010958 0 -0.054965"
      rpy="0 0 0" />
    <parent
      link="link_r_yaw" />
    <child
      link="link_r_roll" />
    <axis
      xyz="1 0 0" />
    <limit
      lower="-0.57"
      upper="0.57"
      effort="12"
      velocity="14" />
  </joint>
  <link
    name="link_r_pitch">
    <inertial>
      <origin
        xyz="-0.0013138 -0.0047951 -0.11962"
        rpy="0 0 0" />
      <mass
        value="0.7406" />
      <inertia
        ixx="0.00149"
        ixy="-5.66E-06"
        ixz="3.397E-05"
        iyy="0.00177728"
        iyz="0.00011861"
        izz="0.00041153" />
    </inertial>
    
    <visual>
      <origin
        xyz="0 0 0"
        rpy="0 0 0" />
      <geometry>
        <mesh
          filename="../meshes/link_r_pitch.STL" />
      </geometry>
      <material
        name="">
        <color
          rgba="1 1 1 1" />
      </material>
    </visual>
    <!-- <collision>
      <origin
        xyz="0 0 0"
        rpy="0 0 0" />
      <geometry>
        <mesh
          filename="../meshes/link_r_pitch.STL" />
      </geometry>
    </collision> -->
  </link>
  <joint
    name="joint_r_pitch"
    type="revolute">
    <origin
      xyz="0.010958 -0.071575 -0.014313"
      rpy="0 0 0" />
    <parent
      link="link_r_roll" />
    <child
      link="link_r_pitch" />
    <axis
      xyz="0 1 0" />
    <limit
      lower="-0.57"
      upper="1.57"
      effort="12"
      velocity="14" />
  </joint>
  <link
    name="link_r_knee">
    <inertial>
      <origin
        xyz="7.3527E-06 0.0067747 -0.11375"
        rpy="0 0 0" />
      <mass
        value="0.4956" />
      <inertia
        ixx="0.00095225"
        ixy="-2E-08"
        ixz="-1.3E-07"
        iyy="0.00104098"
        iyz="-9.514E-05"
        izz="0.00017304" />
    </inertial>
    <visual>
      <origin
        xyz="0 0 0"
        rpy="0 0 0" />
      <geometry>
        <mesh
          filename="../meshes/link_r_knee.STL" />
      </geometry>
      <material
        name="">
        <color
          rgba="1 1 1 1" />
      </material>
    </visual>
    <collision>
      <origin
        xyz="0 0 0"
        rpy="0 0 0" />
      <geometry>
        <mesh
          filename="../meshes/link_r_knee.STL" />
      </geometry>
    </collision>
  </link>
  <joint
    name="joint_r_knee"
    type="revolute">
    <origin
      xyz="0 0 -0.14738"
      rpy="0 0 0" />
    <parent
      link="link_r_pitch" />
    <child
      link="link_r_knee" />
    <axis
      xyz="0 1 0" />
    <limit
      lower="-2.57"
      upper="0.05"
      effort="12"
      velocity="14" />
  </joint>
  <link
    name="link_r_ankle">
    <inertial>
      <origin
        xyz="0.014325 -0.0092777 -0.027539"
        rpy="0 0 0" />
      <mass
        value="0.1122" />
      <inertia
        ixx="4.413E-05"
        ixy="-3.24E-06"
        ixz="5.65E-06"
        iyy="0.00021868"
        iyz="6.84E-06"
        izz="0.00020721" />
    </inertial>
    <visual>
      <origin
        xyz="0 0 0"
        rpy="0 0 0" />
      <geometry>
        <mesh
          filename="../meshes/link_r_ankle.STL" />
      </geometry>
      <material
        name="">
        <color
          rgba="1 1 1 1" />
      </material>
    </visual>
    <collision>
      <origin
        xyz="0.013 -0.005 -0.049"
        rpy="0 0 0" />
      <geometry>
        <box size="0.13 0.04 0.005"/>
      </geometry>
    </collision>
    <!-- <collision>
      <origin
        xyz="0 0 0"
        rpy="0 0 0" />
      <geometry>
        <mesh
          filename="../meshes/link_r_ankle.STL" />
      </geometry>
    </collision> -->
    <!--collision>
      <origin
        xyz="0.02 0 -0.05"
        rpy="0 1.57 0" />
      <geometry>
        <cylinder length="0.13" radius="0.01"/>
      </geometry>
    </collision-->
  </link>
  <joint
    name="joint_r_ankle"
    type="revolute">
    <origin
      xyz="0 0 -0.14049"
      rpy="0 0 0" />
    <parent
      link="link_r_knee" />
    <child
      link="link_r_ankle" />
    <axis
      xyz="0 1 0" />
    <limit
      lower="-0.57"
      upper="1.57"
      effort="6"
      velocity="14" />
  </joint>

  <!--link
    name="link_r_foot">
     <inertial>
      <origin
        xyz="0.020853 0.0048146 -0.030186"
        rpy="0 0 0" />
      <mass
        value="0.01" />
      <inertia
        ixx="0.00001"
        ixy="0.0"
        ixz="0.0"
        iyy="0.00001"
        iyz="0.0"
        izz="0.00001" />
    </inertial>
    <collision>
      <origin
        xyz="0.015 0 0"
        rpy="0 1.54 0" />
      <geometry>
        <cylinder length="0.15" radius="0.01"/>
      </geometry>
    </collision>
  </link>
  <joint
    name="r_foot_joint"
    type="fixed" dont_collapse="true">
    <origin
      xyz="0 0 -0.05"
      rpy="0 0 0" />
    <parent
      link="link_r_ankle" />
    <child
      link="link_r_foot" />
    <axis
      xyz="0 0 0" />
  </joint-->
</robot>
