<?xml version="1.0" encoding="utf-8"?>
<!-- This URDF was automatically created by SolidWorks to URDF Exporter! Originally created by Stephen Brawner (brawner@gmail.com) 
     Commit Version: 1.6.0-1-g15f4949  Build Version: 1.6.7594.29634
     For more information, please see http://wiki.ros.org/sw_urdf_exporter -->
<robot
  name="tinymal">
  <mujoco>
    <compiler 
      meshdir="/home/pi/Downloads/LocomotionWithNP3O-master/resources/tinymal/meshes" 
      balanceinertia="true" 
      discardvisual="false" />
  </mujoco>

  <link
    name="base">
    <inertial>
      <origin
        xyz="-0.00045205 -0.00051396 -0.0066732"
        rpy="0 0 0" />
      <mass
        value="0.8" />
      <inertia
        ixx="0.00036945"
        ixy="1.3188E-07"
        ixz="1.0524E-20"
        iyy="0.00084255"
        iyz="-3.7634E-19"
        izz="0.0010857" />
    </inertial>
    <visual>
      <origin
        xyz="0 0 0"
        rpy="0 0 0" />
      <geometry>
        <mesh
          filename="../meshes/base.STL" />
      </geometry>
      <material
        name="">
        <color
          rgba="1 1 1 1" />
      </material>
    </visual>
    <collision>
      <origin
        xyz="0 0 0"
        rpy="0 0 0" />
      <geometry>
         <box size="0.24 0.0935 0.114" />
      </geometry>
    </collision>
  </link>
  <link
    name="FL_hip">
    <inertial>
      <origin
        xyz="0.028062 -0.0066971 0.00041057"
        rpy="0 0 0" />
      <mass
        value="0.3" />
      <inertia
        ixx="4.8475E-05"
        ixy="1.0083E-05"
        ixz="2.0599E-09"
        iyy="6.1304E-05"
        iyz="1.9321E-08"
        izz="5.1846E-05" />
    </inertial>
    <visual>
      <origin
        xyz="0 0 0"
        rpy="0 0 0" />
      <geometry>
        <mesh
          filename="../meshes/FL_hip.STL" />
      </geometry>
      <material
        name="">
        <color
          rgba="1 1 1 1" />
      </material>
    </visual>
    <collision>
      <origin
        xyz="0.04 0 0"
        rpy="0 0 0" />
      <geometry>
          <cylinder radius="0.03" length="0.03" />
      </geometry>
    </collision>
  </link>
  <joint
    name="FL_hip_joint"
    type="revolute">
    <origin
      xyz="0.117615811341093 0.0448519608147388 0.00119438074225783"
      rpy="0 0 0" />
    <parent
      link="base" />
    <child
      link="FL_hip" />
    <axis
      xyz="1 0 0" />
    <limit
      lower="-0.6"
      upper="0.6"
      effort="12"
      velocity="20" />
  </joint>
  <link
    name="FL_thigh">
    <inertial>
      <origin
        xyz="-4.2324E-05 0.020257 -0.048809"
        rpy="0 0 0" />
      <mass
        value="0.35" />
      <inertia
        ixx="0.00010737"
        ixy="3.8185E-09"
        ixz="-2.2112E-07"
        iyy="0.00013404"
        iyz="-6.7954E-08"
        izz="3.3613E-05" />
    </inertial>
    <visual>
      <origin
        xyz="0 0 0"
        rpy="0 0 0" />
      <geometry>
        <mesh
          filename="../meshes/FL_thigh.STL" />
      </geometry>
      <material
        name="">
        <color
          rgba="0.43922 0.43922 0.43922 1" />
      </material>
    </visual>
    <collision>
      <origin
        xyz="0 0 0"
        rpy="0 0 0" />
      <geometry>
        <mesh
          filename="../meshes/FL_thigh.STL" />
      </geometry>
    </collision>
  </link>
  <joint
    name="FL_thigh_joint"
    type="revolute">
    <origin
      xyz="0.0368115600024336 0.0350142968181736 0"
      rpy="0 -0.000636515673882331 0" />
    <parent
      link="FL_hip" />
    <child
      link="FL_thigh" />
    <axis
      xyz="0 1 0" />
    <limit
      lower="-1.57"
      upper="1.57"
      effort="12"
      velocity="20" />
  </joint>
  <link
    name="FL_calf">
    <inertial>
      <origin
        xyz="-0.010207 -0.0038882 -0.024265"
        rpy="0 0 0" />
      <mass
        value="0.1" />
      <inertia
        ixx="0.00108"
        ixy="3.4E-07"
        ixz="1.72E-05"
        iyy="0.0011"
        iyz="8.28E-06"
        izz="3.29E-05" />
    </inertial>
    <visual>
      <origin
        xyz="0 0 0"
        rpy="0 0 0" />
      <geometry>
        <mesh
          filename="../meshes/FL_calf.STL" />
      </geometry>
      <material
        name="">
        <color
          rgba="1 1 1 1" />
      </material>
    </visual>
    <collision>
      <origin
        xyz="0 0 0"
        rpy="0 0 0" />
      <geometry>
        <mesh
          filename="../meshes/FL_calf.STL" />
      </geometry>
    </collision>
  </link>
  <joint
    name="FL_calf_joint"
    type="revolute">
    <origin
      xyz="-0.000107063240097405 0.0537500000000011 -0.119583203794824"
      rpy="0 -1.2830852687121 0" />
    <parent
      link="FL_thigh" />
    <child
      link="FL_calf" />
    <axis
      xyz="0 -1 0" />
    <limit
      lower="0"
      upper="2.7"
      effort="12"
      velocity="20" />
  </joint>
  <link
    name="FL_foot">
    <inertial>
      <origin
        xyz="0.0140070066713889 8.84950258500383E-05 0.00154864346573341"
        rpy="0 0 0" />
      <mass
        value="0.0137645286881968" />
      <inertia
        ixx="1.41651202823501E-06"
        ixy="2.62369915812515E-10"
        ixz="2.62028073630471E-09"
        iyy="1.15178813885346E-06"
        iyz="-6.55904699891868E-09"
        izz="9.08949663326799E-07" />
    </inertial>
    <visual>
      <origin
        xyz="0 0 0"
        rpy="0 0 0" />
      <geometry>
        <mesh
          filename="../meshes/FL_foot.STL" />
      </geometry>
      <material
        name="">
        <color
          rgba="0.298039215686275 0.298039215686275 0.298039215686275 1" />
      </material>
    </visual>
    <collision>
      <origin
        xyz="0 0 0"
        rpy="0 0 0" />
      <geometry>
       <sphere radius="0.01" />
      </geometry>
    </collision>
  </link>
  <joint
    name="FL_foot_joint"
    type="fixed" dont_collapse="true">
    <origin
      xyz="-0.144829367995569 -0.00756307155902691 -0.0430544596022255"
      rpy="0 0 0" />
    <parent
      link="FL_calf" />
    <child
      link="FL_foot" />
    <axis
      xyz="0 0 0" />
  </joint>
  <link
    name="FR_hip">
    <inertial>
      <origin
        xyz="0.027634 0.0076701 4.7676E-05"
        rpy="0 0 0" />
      <mass
        value="0.3" />
      <inertia
        ixx="4.8531E-05"
        ixy="-1.0208E-05"
        ixz="-2.0599E-09"
        iyy="6.0816E-05"
        iyz="1.9321E-08"
        izz="5.2061E-05" />
    </inertial>
    <visual>
      <origin
        xyz="0 0 0"
        rpy="0 0 0" />
      <geometry>
        <mesh
          filename="../meshes/FR_hip.STL" />
      </geometry>
      <material
        name="">
        <color
          rgba="0.43922 0.43922 0.43922 1" />
      </material>
    </visual>
    <collision>
      <origin
        xyz="0.04 0 0"
        rpy="0 0 0" />
      <geometry>
          <cylinder radius="0.03" length="0.03" />
      </geometry>
    </collision>
  </link>
  <joint
    name="FR_hip_joint"
    type="revolute">
    <origin
      xyz="0.117615811341093 -0.0451480391852612 0.00119438074225779"
      rpy="0 0 0" />
    <parent
      link="base" />
    <child
      link="FR_hip" />
    <axis
      xyz="1 0 0" />
    <limit
      lower="-0.6"
      upper="0.6"
      effort="12"
      velocity="20" />
  </joint>
  <link
    name="FR_thigh">
    <inertial>
      <origin
        xyz="-3.2343E-05 -0.020267 -0.049026"
        rpy="0 0 0" />
      <mass
        value="0.35" />
      <inertia
        ixx="0.0001074"
        ixy="3.9189E-09"
        ixz="1.2398E-07"
        iyy="0.00013404"
        iyz="6.7946E-08"
        izz="3.3633E-05" />
    </inertial>
    <visual>
      <origin
        xyz="0 0 0"
        rpy="0 0 0" />
      <geometry>
        <mesh
          filename="../meshes/FR_thigh.STL" />
      </geometry>
      <material
        name="">
        <color
          rgba="1 1 1 1" />
      </material>
    </visual>
    <collision>
      <origin
        xyz="0 0 0"
        rpy="0 0 0" />
      <geometry>
        <mesh
          filename="../meshes/FR_thigh.STL" />
      </geometry>
    </collision>
  </link>
  <joint
    name="FR_thigh_joint"
    type="revolute">
    <origin
      xyz="0.0368115600024335 -0.0350142968181737 0"
      rpy="0 0.000636515673882331 0" />
    <parent
      link="FR_hip" />
    <child
      link="FR_thigh" />
    <axis
      xyz="0 1 0" />
    <limit
      lower="-1.57"
      upper="1.57"
      effort="12"
      velocity="20" />
  </joint>
  <link
    name="FR_calf">
    <inertial>
      <origin
        xyz="-0.0095307 0.0038882 -0.024265"
        rpy="0 0 0" />
      <mass
        value="0.1" />
      <inertia
        ixx="0.00108"
        ixy="3.4E-07"
        ixz="1.72E-05"
        iyy="0.0011"
        iyz="8.28E-06"
        izz="3.29E-05" />
    </inertial>
    <visual>
      <origin
        xyz="0 0 0"
        rpy="0 0 0" />
      <geometry>
        <mesh
          filename="../meshes/FR_calf.STL" />
      </geometry>
      <material
        name="">
        <color
          rgba="1 1 1 1" />
      </material>
    </visual>
    <collision>
      <origin
        xyz="0 0 0"
        rpy="0 0 0" />
      <geometry>
        <mesh
          filename="../meshes/FR_calf.STL" />
      </geometry>
    </collision>
  </link>
  <joint
    name="FR_calf_joint"
    type="revolute">
    <origin
      xyz="-0.000191532759080459 -0.0537499999999988 -0.120380600355233"
      rpy="0 -1.2800888506786 0" />
    <parent
      link="FR_thigh" />
    <child
      link="FR_calf" />
    <axis
      xyz="0 -1 0" />
    <limit
      lower="0"
      upper="2.7"
      effort="12"
      velocity="20" />
  </joint>
  <link
    name="FR_foot">
    <inertial>
      <origin
        xyz="0.00151098287577117 0.0140070063422869 0.000350800090631626"
        rpy="0 0 0" />
      <mass
        value="0.0137645300163555" />
      <inertia
        ixx="9.18185504610776E-07"
        ixy="2.53738927115051E-09"
        ixz="-4.69096621298054E-08"
        iyy="1.41651226312419E-06"
        iyz="7.04625726773317E-10"
        izz="1.14255241456168E-06" />
    </inertial>
    <visual>
      <origin
        xyz="0 0 0"
        rpy="0 0 0" />
      <geometry>
        <mesh
          filename="../meshes/FR_foot.STL" />
      </geometry>
      <material
        name="">
        <color
          rgba="0.298039215686275 0.298039215686275 0.298039215686275 1" />
      </material>
    </visual>
    <collision>
      <origin
        xyz="0 0 0"
        rpy="0 0 0" />
      <geometry>
             <sphere radius="0.01" />
      </geometry>
    </collision>
  </link>
  <joint
    name="FR_foot_joint"
    type="fixed" dont_collapse="true">
    <origin
      xyz="-0.144255308338313 0.00743692844097307 -0.0430544596022255"
      rpy="0 -1.39975108426149 -1.5707963267949" />
    <parent
      link="FR_calf" />
    <child
      link="FR_foot" />
    <axis
      xyz="0 0 0" />
  </joint>
  <link
    name="RL_hip">
    <inertial>
      <origin
        xyz="-0.027634 -0.0076701 4.7676E-05"
        rpy="0 0 0" />
      <mass
        value="0.3" />
      <inertia
        ixx="4.8531E-05"
        ixy="-1.0208E-05"
        ixz="2.0599E-09"
        iyy="6.0816E-05"
        iyz="-1.9321E-08"
        izz="5.2061E-05" />
    </inertial>
    <visual>
      <origin
        xyz="0 0 0"
        rpy="0 0 0" />
      <geometry>
        <mesh
          filename="../meshes/RL_hip.STL" />
      </geometry>
      <material
        name="">
        <color
          rgba="1 1 1 1" />
      </material>
    </visual>
    <collision>
      <origin
        xyz="-0.04 0 0"
        rpy="0 0 0" />
      <geometry>
          <cylinder radius="0.03" length="0.03" />
      </geometry>
    </collision>
  </link>
  <joint
    name="RL_hip_joint"
    type="revolute">
    <origin
      xyz="-0.115396683031257 0.0448519608147397 0.00119438074225779"
      rpy="0 0 0" />
    <parent
      link="base" />
    <child
      link="RL_hip" />
    <axis
      xyz="1 0 0" />
    <limit
      lower="-0.6"
      upper="0.6"
      effort="12"
      velocity="20" />
  </joint>
  <link
    name="RL_thigh">
    <inertial>
      <origin
        xyz="6.3356E-05 0.020267 -0.049026"
        rpy="0 0 0" />
      <mass
        value="0.35" />
      <inertia
        ixx="0.0001074"
        ixy="3.9621E-09"
        ixz="-7.6672E-08"
        iyy="0.00013404"
        iyz="-6.7944E-08"
        izz="3.3634E-05" />
    </inertial>
    <visual>
      <origin
        xyz="0 0 0"
        rpy="0 0 0" />
      <geometry>
        <mesh
          filename="../meshes/RL_thigh.STL" />
      </geometry>
      <material
        name="">
        <color
          rgba="1 1 1 1" />
      </material>
    </visual>
    <collision>
      <origin
        xyz="0 0 0"
        rpy="0 0 0" />
      <geometry>
        <mesh
          filename="../meshes/RL_thigh.STL" />
      </geometry>
    </collision>
  </link>
  <joint
    name="RL_thigh_joint"
    type="revolute">
    <origin
      xyz="-0.0368115600024335 0.0350142968181737 0"
      rpy="0 0 0" />
    <parent
      link="RL_hip" />
    <child
      link="RL_thigh" />
    <axis
      xyz="0 -1 0" />
    <limit
      lower="-1.57"
      upper="1.57"
      effort="12"
      velocity="20" />
  </joint>
  <link
    name="RL_calf">
    <inertial>
      <origin
        xyz="-0.0095307 -0.0038882 0.024265"
        rpy="0 0 0" />
      <mass
        value="0.1" />
      <inertia
        ixx="0.00108"
        ixy="3.4E-07"
        ixz="1.72E-05"
        iyy="0.0011"
        iyz="8.28E-06"
        izz="3.29E-05" />
    </inertial>
    <visual>
      <origin
        xyz="0 0 0"
        rpy="0 0 0" />
      <geometry>
        <mesh
          filename="../meshes/RL_calf.STL" />
      </geometry>
      <material
        name="">
        <color
          rgba="1 1 1 1" />
      </material>
    </visual>
    <collision>
      <origin
        xyz="0 0 0"
        rpy="0 0 0" />
      <geometry>
        <mesh
          filename="../meshes/RL_calf.STL" />
      </geometry>
    </collision>
  </link>
  <joint
    name="RL_calf_joint"
    type="revolute">
    <origin
      xyz="0.000259006728275737 0.0537500000000001 -0.120384637489192"
      rpy="-3.14159265358979 -1.3033681821733 3.14159265358979" />
    <parent
      link="RL_thigh" />
    <child
      link="RL_calf" />
    <axis
      xyz="0 1 0" />
    <limit
      lower="0"
      upper="2.7"
      effort="12"
      velocity="20" />
  </joint>
  <link
    name="RL_foot">
    <inertial>
      <origin
        xyz="0.0140071245179277 8.855357142111E-05 0.00154866912218975"
        rpy="0 0 0" />
      <mass
        value="0.0137644088279976" />
      <inertia
        ixx="1.41649890685894E-06"
        ixy="2.67731870932616E-10"
        ixz="2.62800977802519E-09"
        iyy="1.1517685962269E-06"
        iyz="-6.56885017477171E-09"
        izz="9.08962872324671E-07" />
    </inertial>
    <visual>
      <origin
        xyz="0 0 0"
        rpy="0 0 0" />
      <geometry>
        <mesh
          filename="../meshes/RL_foot.STL" />
      </geometry>
      <material
        name="">
        <color
          rgba="0.298039215686275 0.298039215686275 0.298039215686275 1" />
      </material>
    </visual>
    <collision>
      <origin
        xyz="0 0 0"
        rpy="0 0 0" />
      <geometry>
             <sphere radius="0.01" />
      </geometry>
    </collision>
  </link>
  <joint
    name="RL_foot_joint"
    type="fixed" dont_collapse="true">
    <origin
      xyz="-0.14426 -0.0075631 0.039712"
      rpy="0 0 0" />
    <parent
      link="RL_calf" />
    <child
      link="RL_foot" />
    <axis
      xyz="0 0 0" />
  </joint>
  <link
    name="RR_hip">
    <inertial>
      <origin
        xyz="-0.027634 0.0076701 -4.7676E-05"
        rpy="0 0 0" />
      <mass
        value="0.3" />
      <inertia
        ixx="4.8531E-05"
        ixy="1.0208E-05"
        ixz="-2.0599E-09"
        iyy="6.0816E-05"
        iyz="-1.9321E-08"
        izz="5.2061E-05" />
    </inertial>
    <visual>
      <origin
        xyz="0 0 0"
        rpy="0 0 0" />
      <geometry>
        <mesh
          filename="../meshes/RR_hip.STL" />
      </geometry>
      <material
        name="">
        <color
          rgba="1 1 1 1" />
      </material>
    </visual>
    <collision>
      <origin
        xyz="-0.04 0 0"
        rpy="0 0 0" />
      <geometry>
          <cylinder radius="0.03" length="0.03" />
      </geometry>
    </collision>
  </link>
  <joint
    name="RR_hip_joint"
    type="revolute">
    <origin
      xyz="-0.1154 -0.045148 0.0011944"
      rpy="0 0 0" />
    <parent
      link="base" />
    <child
      link="RR_hip" />
    <axis
      xyz="1 0 0" />
    <limit
      lower="-0.6"
      upper="0.6"
      effort="12"
      velocity="20" />
  </joint>
  <link
    name="RR_thigh">
    <inertial>
      <origin
        xyz="1.138E-05 -0.020257 -0.048809"
        rpy="0 0 0" />
      <mass
        value="0.35" />
      <inertia
        ixx="0.00010737"
        ixy="3.8617E-09"
        ixz="1.7448E-07"
        iyy="0.00013404"
        iyz="6.7951E-08"
        izz="3.3613E-05" />
    </inertial>
    <visual>
      <origin
        xyz="0 0 0"
        rpy="0 0 0" />
      <geometry>
        <mesh
          filename="../meshes/RR_thigh.STL" />
      </geometry>
      <material
        name="">
        <color
          rgba="0.43922 0.43922 0.43922 1" />
      </material>
    </visual>
    <collision>
      <origin
        xyz="0 0 0"
        rpy="0 0 0" />
      <geometry>
        <mesh
          filename="../meshes/RR_thigh.STL" />
      </geometry>
    </collision>
  </link>
  <joint
    name="RR_thigh_joint"
    type="revolute">
    <origin
      xyz="-0.0368115600024335 -0.0350142968181737 0"
      rpy="0 0 0" />
    <parent
      link="RR_hip" />
    <child
      link="RR_thigh" />
    <axis
      xyz="0 -1 0" />
    <limit
      lower="-1.57"
      upper="1.57"
      effort="12"
      velocity="20" />
  </joint>
  <link
    name="RR_calf">
    <inertial>
      <origin
        xyz="-0.010207 0.0038882 0.024265"
        rpy="0 0 0" />
      <mass
        value="0.1" />
      <inertia
        ixx="0.00108"
        ixy="3.4E-07"
        ixz="1.72E-05"
        iyy="0.0011"
        iyz="8.28E-06"
        izz="3.29E-05" />
    </inertial>
    <visual>
      <origin
        xyz="0 0 0"
        rpy="0 0 0" />
      <geometry>
        <mesh
          filename="../meshes/RR_calf.STL" />
      </geometry>
      <material
        name="">
        <color
          rgba="1 1 1 1" />
      </material>
    </visual>
    <collision>
      <origin
        xyz="0 0 0"
        rpy="0 0 0" />
      <geometry>
        <mesh
          filename="../meshes/RR_calf.STL" />
      </geometry>
    </collision>
  </link>
  <joint
    name="RR_calf_joint"
    type="revolute">
    <origin
      xyz="3.67726187057993E-05 -0.05375 -0.119582482181542"
      rpy="3.14159265358979 -1.29768930288204 -3.14159265358979" />
    <parent
      link="RR_thigh" />
    <child
      link="RR_calf" />
    <axis
      xyz="0 1 0" />
    <limit
      lower="0"
      upper="2.7"
      effort="12"
      velocity="20" />
  </joint>
  <link
    name="RR_foot">
    <inertial>
      <origin
        xyz="0.014007007744901 -8.85016716011822E-05 -0.00154864117653222"
        rpy="0 0 0" />
      <mass
        value="0.0137645245059238" />
      <inertia
        ixx="1.41651128321489E-06"
        ixy="-2.62126080902366E-10"
        ixz="-2.62021598378361E-09"
        iyy="1.15178801247998E-06"
        iyz="-6.55995398788169E-09"
        izz="9.08949425805397E-07" />
    </inertial>
    <visual>
      <origin
        xyz="0 0 0"
        rpy="0 0 0" />
      <geometry>
        <mesh
          filename="../meshes/RR_foot.STL" />
      </geometry>
      <material
        name="">
        <color
          rgba="0.298039215686275 0.298039215686275 0.298039215686275 1" />
      </material>
    </visual>
    <collision>
      <origin
        xyz="0 0 0"
        rpy="0 0 0" />
      <geometry>
             <sphere radius="0.01" />
      </geometry>
    </collision>
  </link>
  <joint
    name="RR_foot_joint"
    type="fixed" dont_collapse="true">
    <origin
      xyz="-0.14483 0.0075631 0.043054"
      rpy="0 0 0" />
    <parent
      link="RR_calf" />
    <child
      link="RR_foot" />
    <axis
      xyz="0 0 0" />
  </joint>
</robot>